Workbook
Name SegmentaçãodeDados_ANO_AVAL.: #N/A
Name SegmentaçãodeDados_ANO_AVAL.1: #N/A
Name SegmentaçãodeDados_CAMPUS1: #N/A
Name SegmentaçãodeDados_CAMPUS11: #N/A
Name SegmentaçãodeDados_CC: #N/A
Name SegmentaçãodeDados_CC1: #N/A
Name SegmentaçãodeDados_COD_AVAL: #N/A
Name SegmentaçãodeDados_COD_AVAL1: #N/A
Name SegmentaçãodeDados_COD_CURSO: #N/A
Name SegmentaçãodeDados_COD_CURSO1: #N/A
Name SegmentaçãodeDados_CURSO1: #N/A
Name SegmentaçãodeDados_CURSO11: #N/A
Name SegmentaçãodeDados_D1: #N/A
Name SegmentaçãodeDados_D11: #N/A
Name SegmentaçãodeDados_D2: #N/A
Name SegmentaçãodeDados_D21: #N/A
Name SegmentaçãodeDados_D3: #N/A
Name SegmentaçãodeDados_D31: #N/A
Name SegmentaçãodeDados_MOD: #N/A
Name SegmentaçãodeDados_MOD1: #N/A
Name SegmentaçãodeDados_PROC._Nº: #N/A
Name SegmentaçãodeDados_PROC._Nº1: #N/A
Name SegmentaçãodeDados_UND_ACAD1: #N/A
Name SegmentaçãodeDados_UND_ACAD11: #N/A

Sheet BASE IN-LOCO
A1: CURSO | B1: CAMPUS | C1: UND-ACAD | D1: ANO | E1: D1 | F1: D2 | G1: D3 | H1: CC | I1: AVAL
A2: ENG. QUÍMICA | B2: BELÉM | C2: ITEC | D2: 2011 | E2: 2 | F2: 4 | G2: 3 | H2: 3 | I2: 2
A3: QUÍMICA - BACHARELADO | B3: BELÉM | C3: ICEN | D3: 2011 | E3: 3 | F3: 4 | G3: 3 | H3: 3 | I3: 3
A4: ENG. MECÂNICA | B4: BELÉM | C4: ITEC | D4: 2011 | E4: 3 | F4: 3 | G4: 2 | H4: 3 | I4: 3
A5: COMUNICAÇÃO SOCIAL | B5: BELÉM | C5: ILC | D5: 2011 | E5: 3 | F5: 4 | G5: 2 | H5: 3 | I5: 3
A6: ENG. ELÉTRICA | B6: BELÉM | C6: ITEC | D6: 2011 | E6: 2 | F6: 4 | G6: 3 | H6: 3 | I6: 2
A7: FÍSICA | B7: BELÉM | C7: ICEN | D7: 2011 | E7: 3 | F7: 4 | G7: 3 | H7: 3 | I7: 3
A8: CIÊNCIAS SOCIAIS - BACHARELADO | B8: BELÉM | C8: IFCH | D8: 2011 | E8: 3 | F8: 5 | G8: 2 | H8: 3 | I8: 3
A9: CIÊNCIAS SOCIAIS - LICENCIATURA | B9: BELÉM | C9: IFCH | D9: 2011 | E9: 3 | F9: 5 | G9: 2 | H9: 3 | I9: 3
A10: ENG. NAVAL | B10: BELÉM | C10: ITEC | D10: 2011 | E10: 5 | F10: 5 | G10: 5 | H10: 5 | I10: 4
A11: ESTATÍSTICA | B11: BELÉM | C11: ICEN | D11: 2011 | E11: 2 | F11: 4 | G11: 2 | H11: 3 | I11: 2
A12: MÚSICA | B12: BELÉM | C12: ICA | D12: 2011 | E12: 4 | F12: 4 | G12: 2 | H12: 4 | I12: 3
A13: EDUCAÇÃO FÍSICA | B13: BELÉM | C13: ICED | D13: 2011 | E13: 4 | F13: 4 | G13: 4 | H13: 4 | I13: 2
... A122: ENG. FERROVIÁRIA | B122: BELÉM | C122: ITEC | D122: 2017 | E122: 3.3 | F122: 4.3 | G122: 2.6 | H122: 3 | I122: 3
A123: CIÊNCIAS NATURAIS | B123: BREVES | C123: BRV | D123: 2018 | E123: 4,19 | F123: 4,42 | G123: 3,88 | H123: 4 | I123: 3
A124: ENG. DA COMPUTAÇÃO | B124: TUCURUÍ | C124: TUC | D124: 2018 | E124: 3,6 | F124: 4,46 | G124: 2,9 | H124: 4 | I124: 3
A125: FARMÁCIA | B125: BELÉM | C125: ICS | D125: 2018 | E125: 4,39 | F125: 4,75 | G125: 3,81 | H125: 4 | I125: 3
A126: Fisioterapia | B126: BELÉM | C126: ICS | D126: 2018 | E126: 4,59 | F126: 4,91 | G126: 4,77 | H126: 5 | I126: 4
A127: ENG. DE PESCA | B127: BRAGANÇA | C127: BRG | D127: 2018 | E127: 4,47 | F127: 4,64 | G127: 3,91 | H127: 4 | I127: 5
A128: ENG. DA COMPUTAÇÃO | B128: CASTANHAL | C128: CST | D128: 2018 | E128: 3,65 | F128: 4,14 | G128: 3,4 | H128: 4 | I128: 3
A129: EDUCAÇÃO DO CAMPO | B129: ALTAMIRA | C129: ALT | D129: 2018 | E129: 4,65 | F129: 5 | G129: 4,22 | H129: 5 | I129: 4
A130: MÚSICA | B130: BELÉM | C130: ICA | D130: 2018 | E130: 4,4 | F130: 4,17 | G130: 2,82 | H130: 4 | I130: 3
A131: GEOGRAFIA | B131: CAMETÁ | C131: CMT | D131: 2018 | E131: 3,7 | F131: 4,58 | G131: 3 | H131: 4 | I131: 4
A132: CIENCIAS SOCIAIS | B132: BELÉM | C132: IFCH | D132: 2018 | E132: 3,2 | F132: 4,73 | G132: 4 | H132: 4 | I132: 4
A133: LETRAS - PORTUGUÊS | B133: BELÉM | C133: ILC | D133: 2018 | E133: 4,5 | F133: 4,25 | G133: 3,25 | H133: 4 | I133: 4
A134: Eng. Florestal | B134: ALTAMIRA | C134: ALT | D134: 2018 | E134: 3.67 | F134: 4.18 | G134: 3.4 | H134: 4 | I134: 2
A135: Biotecnologia | B135: BELÉM | C135: ICB | D135: 2018 | E135: 4 | F135: 4.64 | G135: 4.13 | H135: 4 | I135: 3
A136: INTER-DISCIPLINAR INTEGRADA EM EDUCAÇÃO, CIÊNCIAS, MATEMÁTICA E LINGUAGEM | B136: BELÉM | C136: IEMCI | D136: 2018 | E136: 4 | F136: 4.92 | G136: 4.3 | H136: 4 | I136: 4
A137: LETRAS ALEMÃO | B137: BELÉM | C137: ILC | D137: 2018 | E137: 4.8 | F137: 3.31 | G137: 4.82 | H137: 4 | I137: 4
A138: LETRAS-INGLÊS | B138: BELÉM | C138: ILC | D138: 2018 | E138: 3.75 | F138: 3.91 | G138: 4 | H138: 4 | I138: 3
A139: LETRAS - FRANCES | B139: BELÉM | C139: ILC | D139: 2018 | E139: 3.65 | F139: 4.46 | G139: 4.2 | H139: 4 | I139: 3
A140: LETRAS - ESPANHOL | B140: BELÉM | C140: ILC | D140: 2018 | E140: 3.6 | F140: 3.64 | G140: 4 | H140: 4 | I140: 3
A141: OCEANOGRAFIA | B141: BELÉM | C141: IG | D141: 2018 | E141: 3.21 | F141: 4.46 | G141: 3.44 | H141: 4 | I141: 3
A142: LETRAS - PORTUGUÊS | B142: ABAETETUBA | C142: ABT | D142: 2018 | E142: 3.25 | F142: 4.08 | G142: 2.91 | H142: 3 | I142: 4
A143: LETRAS-INGLÊS | B143: CAMETÁ | C143: CMT | D143: 2018 | E143: 2.9 | F143: 4.25 | G143: 3 | H143: 3 | I143: 2
A144: MATEMÁTICA | B144: SALINOPOLIS | C144: SAL | D144: 2018 | E144: 4.11 | F144: 4 | G144: 4 | H144: 4 | I144: 3
A145: ENG. MECÂNICA | B145: TUCURUÍ | C145: TUC | D145: 2018 | E145: 3.73 | F145: 4.09 | G145: 3.1 | H145: 4 | I145: 4
A146: Biblioteconomia | B146: BELÉM | C146: ICSA | D146: 2018 | E146: 3.86 | F146: 4.33 | G146: 4.25 | H146: 4 | I146: 4
A147: HISTÓRIA | B147: ANANINDEUA | C147: ANA | D147: 2018 | E147: 4.28 | F147: 4.44 | G147: 3 | H147: 4 | I147: 1
A148: FÍSICA | B148: ANANINDEUA | C148: ANA | D148: 2019 | E148: 3.89 | F148: 3.67 | G148: 2.63 | H148: 3 | I148: 1
...

Sheet CAPA
A1: UNIVERSIDADE FEDERAL DO PARA
A2: PRÓ-REITORIA DE PLANEJAMENTO E DESENVOLVIMENTO INSTITUCIONAL
A3: DIRETORIA DE AVALIAÇÃO INSTITUCIONAL
A4: COORDENADORIA DE AUTOAVALIAÇÃO

Sheet INSTRUMENTOS
A1: UNIVERSIDADE FEDERAL DO PARA
A2: PRÓ-REITORIA DE PLANEJAMENTO E DESENVOLVIMENTO INSTITUCIONAL
A3: DIRETORIA DE AVALIAÇÃO INSTITUCIONAL
A4: COORDENADORIA DE AUTOAVALIAÇÃO

Sheet 2011
A1: UNIVERSIDADE FEDERAL DO PARA
A2: PRÓ-REITORIA DE PLANEJAMENTO E DESENVOLVIMENTO INSTITUCIONAL
A3: DIRETORIA DE AVALIAÇÃO INSTITUCIONAL
A4: COORDENADORIA DE AUTOAVALIAÇÃO
D9: MOSTRA O RELATÓRIO DA AVALIAÇÃO
A12: CURSO | B12: MOD | C12: COD-CURSO | D12: CAMPUS | E12: UND-ACAD | F12: PROC. Nº | G12: COD-AVAL | H12: ANO AVAL. | I12: PERÍODO | J12: D1 | K12: D2 | L12: D3 | M12: CC | N12: AVAL
A13: ENGENHARIA QUÍMICA | B13: BACH | D13: BELÉM | E13: ITEC | F13: 201102682 | G13: 89288 | H13: 2011 | I13: 40677 | J13: 2 | K13: 4 | L13: 3 | M13: 3 | N13: 2
A14: QUÍMICA | B14: BACH | D14: BELÉM | E14: ICEN | F14: 201101981 | G14: 89629 | H14: 2011 | I14: 19 A 22/06/11 | J14: 3 | K14: 4 | L14: 3 | M14: 3 | N14: 3
A15: ENGENHARIA MECÂNICA | B15: BACH | D15: BELÉM | E15: ITEC | F15: 201101816 | G15: 89285 | H15: 2011 | I15: 26 A 29/06/11 | J15: 3 | K15: 3 | L15: 2 | M15: 3 | N15: 3
A16: COMUNICAÇÃO SOCIAL | B16: BACH | D16: BELÉM | E16: ILC | F16: 201101868 | G16: 89286 | H16: 2011 | I16: 26 A 29/06/11 | J16: 3 | K16: 4 | L16: 2 | M16: 3 | N16: 3
A17: ENGENHARIA ELÉTRICA | B17: BACH | D17: BELÉM | E17: ITEC | F17: 201101219 | G17: 89277 | H17: 2011 | I17: 17 A 20/08/11 | J17: 2 | K17: 4 | L17: 3 | M17: 3 | N17: 2
A18: FÍSICA - LICENCIATURA | B18: LIC | D18: BELÉM | E18: ICEN | F18: 201101549 | G18: 89689 | H18: 2011 | I18: 17 A 20/08/11 | J18: 3 | K18: 4 | L18: 3 | M18: 3 | N18: 3
A19: CIÊNCIAS SOCIAIS - BACHARELADO | B19: BACH | D19: BELÉM | E19: IFCH | F19: 201102336 | G19: 90053 | H19: 2011 | I19: 14 A 17/09/11 | J19: 3 | K19: 5 | L19: 2 | M19: 3 | N19: 3 | O19: IMP.SERES
A20: CIÊNCIAS SOCIAIS - LICENCIATURA | B20: LIC | D20: BELÉM | E20: IFCH | F20: 201102881 | G20: 90059 | H20: 2011 | I20: 14 A 17/09/11 | J20: 3 | K20: 5 | L20: 2 | M20: 3 | N20: 3 | O20: IMP.SERES
A21: ENGENHARIA NAVAL | B21: BACH | D21: BELÉM | E21: ITEC | F21: 200902233 | G21: 84354 | H21: 2011 | I21: 18 A 21/09/11 | J21: 5 | K21: 5 | L21: 5 | M21: 5 | N21: 4
A22: ESTATÍSTICA | B22: BACH | D22: BELÉM | E22: ICEN | F22: 201101331 | G22: 89456 | H22: 2011 | I22: 26 A 29/10/11 | J22: 2 | K22: 4 | L22: 2 | M22: 3 | N22: 2
A23: MÚSICA | B23: LIC | D23: BELÉM | E23: ICA | F23: 201007619 | G23: 85732 | H23: 2011 | I23: 16 A 19/11/11 | J23: 4 | K23: 4 | L23: 2 | M23: 4 | N23: 3
A24: EDUCAÇÃO FÍSICA | B24: LIC | D24: BELÉM | E24: ICED | F24: 200905989 | G24: 84356 | H24: 2010 | I24: 21 A 24/11/11 | J24: 4 | K24: 4 | L24: 4 | M24: 4 | N24: 2
A25: MATEMÁTICA | B25: LIC | D25: ABAETETUBA | E25: ABT | F25: 201101188 | G25: 89275 | H25: 2011 | I25: 24 A 17/08/11 | J25: 3 | K25: 3 | L25: 3 | M25: 3 | N25: 1
A26: PEDAGOGIA | B26: LIC | D26: BRAGANÇA | E26: BRG | F26: 201101182 | G26: 89582 | H26: 2011 | I26: 18 A 21/05/11 | J26: 3 | K26: 3 | L26: 2 | M26: 3 | N26: 3
A27: PEDAGOGIA | B27: LIC | D27: BREVES | E27: BRV | F27: 201101283 | G27: 89279 | H27: 2011 | I27: 27/09 A 01/10/11 | J27: 3 | K27: 3 | L27: 2 | M27: 3 | N27: 3
A28: LETRAS | B28: LIC | D28: BREVES | E28: BRV | F28: 201101503 | G28: 89587 | H28: 2011 | I28: 29/11 A 03/12/11 | J28: 3 | K28: 3 | L28: 2 | M28: 3 | N28: 3
A29: ENGENHARIA DE MATERIAIS | B29: BACH | D29: MARABÁ | E29: MRB | F29: 200812042 | G29: 82698 | H29: 2011 | I29: 23 A 26/03/11 | J29: 4 | K29: 4 | L29: 4 | M29: 4 | N29: 4
A30: ENGENHARIA DE MINAS | B30: BACH | D30: MARABÁ | E30: MRB | F30: 200900270 | G30: 84741 | H30: 2011 | I30: 21 A 24/08/11 | J30: 4 | K30: 4 | L30: 3 | M30: 4 | N30: 4
I31: Média | J31: =AVERAGE(J13:J18,J21:J30) -> 3.1875 | K31: =AVERAGE(K13:K18,K21:K30) -> 3.75 | L31: =AVERAGE(L13:L18,L21:L30) -> 2.8125 | M31: =AVERAGE(M13:M18,M21:M30) -> 3.375 | N31: =AVERAGE(N13:N18,N21:N30) -> 2.8125

Sheet 2011 (GRAF)
A1: UNIVERSIDADE FEDERAL DO PARA
A2: PRÓ-REITORIA DE PLANEJAMENTO E DESENVOLVIMENTO INSTITUCIONAL
A3: DIRETORIA DE AVALIAÇÃO INSTITUCIONAL
A4: COORDENADORIA DE AUTOAVALIAÇÃO
B14: MÉDIA POR UND-ACAD
C15: D1 | D15: D2 | E15: D3
B16: ITEC | C16: =AVERAGE('2011'!J13,'2011'!J15,'2011'!J17,'2011'!J21) -> 3 | D16: =AVERAGE('2011'!K13,'2011'!K15,'2011'!K17,'2011'!K21) -> 4 | E16: =AVERAGE('2011'!L13,'2011'!L15,'2011'!L17,'2011'!L21) -> 3.25
B17: ICEN | C17: =AVERAGE('2011'!J14,'2011'!J18,'2011'!J22) -> 2.6666667 | D17: =AVERAGE('2011'!K14,'2011'!K18,'2011'!K22) -> 4 | E17: =AVERAGE('2011'!L14,'2011'!L18,'2011'!L22) -> 2.6666667
B18: ILC | C18: =AVERAGE('2011'!J16) -> 3 | D18: =AVERAGE('2011'!K16) -> 4 | E18: =AVERAGE('2011'!L16) -> 2
B19: IFCH | C19: 0 | D19: 0 | E19: 0
B20: ICA | C20: =AVERAGE('2011'!J23) -> 4 | D20: =AVERAGE('2011'!K23) -> 4 | E20: =AVERAGE('2011'!L23) -> 2
B21: ICED | C21: =AVERAGE('2011'!J24) -> 4 | D21: =AVERAGE('2011'!K24) -> 4 | E21: =AVERAGE('2011'!L24) -> 4
B22: ABT | C22: =AVERAGE('2011'!J25) -> 3 | D22: =AVERAGE('2011'!K25) -> 3 | E22: =AVERAGE('2011'!L25) -> 3
B23: BRG | C23: =AVERAGE('2011'!J26) -> 3 | D23: =AVERAGE('2011'!K26) -> 3 | E23: =AVERAGE('2011'!L26) -> 2
B24: BRV | C24: =AVERAGE('2011'!J27,'2011'!J28) -> 3 | D24: =AVERAGE('2011'!K27,'2011'!K28) -> 3 | E24: =AVERAGE('2011'!L27,'2011'!L28) -> 2
B25: MRB | C25: =AVERAGE('2011'!J29:J30) -> 4 | D25: =AVERAGE('2011'!K29:K30) -> 4 | E25: =AVERAGE('2011'!L29:L30) -> 3.5
A36: D1 - ORGANIZAÇÃO DIDÁTICO-PEDAGÓGICA - Fontes de Consulta: Plano de Desenvolvimento Institucional, Projeto Pedagógico do Curso, Relatório de Autoavaliação Institucional, Políticas Institucionais, Diretrizes Curriculares Nacionais, quando houver, Catálogo Nacional dos Cursos Superiores de Tecnologia, quando couber, Formulário Eletrônico preenchido pela IES no e-MEC.
A38: D2 - CORPO DOCENTE E TUTORIAL - Fontes de consulta: Projeto Pedagógico do Curso, Plano de Desenvolvimento Institucional, Políticas de Formação Docente, Formulário Eletrônico preenchido pela IES no e-MEC, Documentação Comprobatória e Catálogo Nacional dos Cursos Superiores de Tecnologia, quando couber.
A40: D3 - INFRAESTRUTURA - Fontes de Consulta: Projeto Pedagógico do Curso, Diretrizes Curriculares Nacionais, quando houver, Catálogo Nacional dos Cursos Superiores de Tecnologia, quando couber. Formulário Eletrônico preenchido pela IES no e-MEC e Documentação Comprobatória.

Sheet 2012
A1: UNIVERSIDADE FEDERAL DO PARA
A2: PRÓ-REITORIA DE PLANEJAMENTO E DESENVOLVIMENTO INSTITUCIONAL
A3: DIRETORIA DE AVALIAÇÃO INSTITUCIONAL
A4: COORDENADORIA DE AUTOAVALIAÇÃO
D9: MOSTRA O RELATÓRIO DA AVALIAÇÃO
A12: CURSO | B12: MOD | C12: COD-CURSO | D12: CAMPUS | E12: UND-ACAD | F12: PROC. Nº | G12: COD-AVAL | H12: ANO AVAL. | I12: PERÍODO | J12: D1 | K12: D2 | L12: D3 | M12: CC | N12: AVAL
A13: SISTEMA DE INFORMAÇÃO | B13: BACH | D13: CASTANHAL | E13: CST | F13: 201203993 | G13: 96801 | H13: 2012 | I13: 24 A 27/02/2012 | J13: 2.7 | K13: 3.9 | L13: 2.6 | M13: 3 | N13: 1
A14: MATEMATICA | B14: LIC | D14: CAMETÁ | E14: CMT | F14: 201202145 | G14: 96718 | H14: 2012 | I14: 24 A 27/02/2012 | J14: 2.9 | K14: 4.1 | L14: 1.6 | M14: 3 | N14: 3
A15: LETRAS PORTUGUÊS | B15: LIC | D15: ALTAMIRA | E15: ALT | F15: 201201183 | G15: 96312 | H15: 2012 | I15: 12/12 A 15/12/2012 | J15: 3.2 | K15: 4.3 | L15: 2.1 | M15: 3 | N15: 3
A16: LETRAS ALEMÃO | B16: LIC | D16: BELÉM | E16: ILC | F16: 201100607 | G16: 93434 | H16: 2012 | I16: 08/08 A 11/08/2012 | J16: 3.5 | K16: 3.4 | L16: 3.6 | M16: 4 | N16: 3
A17: HISTÓRIA | B17: LIC | D17: CAMETÁ | E17: IFCH | F17: 201201787 | G17: 96713 | H17: 2012 | I17: 04/11 A 07/11/2012 | J17: 3 | K17: 4.3 | L17: 1.9 | M17: 3 | N17: 3
A18: GEOLOGIA | B18: BACH | D18: BELÉM | E18: IG | F18: 201114820 | G18: 95661 | H18: 2012 | I18: 15 A 18/08/2012 | J18: 4.4 | K18: 4.3 | L18: 4.3 | M18: 4 | N18: 4
A19: GEOLOGIA | B19: BACH | D19: MARABÁ | E19: MRB | F19: 201113411 | G19: 94201 | H19: 2012 | I19: 01/08 A 04/08/2012 | J19: 3.1 | K19: 4.1 | L19: 3.3 | M19: 3 | N19: 1
A20: ENG. SANITARIA E AMBIENTAL | B20: BACH | D20: BELÉM | E20: ITEC | F20: 201008291 | G20: 85797 | H20: 2012 | I20: 21 A 24/11/12 | J20: 5 | K20: 5 | L20: 4 | M20: 5 | N20: 3
A21: ENG. FLORESTAL | B21: BACH | D21: ALTAMIRA | E21: ALT | F21: 201200645 | G21: 96306 | H21: 2012 | I21: 19 a 22/08/12 | J21: 3.3 | K21: 3.5 | L21: 3.3 | M21: 3 | N21: 2
A22: EAD QUIMICA | B22: LIC | D22: BELÉM | E22: ICEN | F22: 201113636 | G22: 96694 | H22: 2012 | I22: 04/11 A 07/11/2012 | J22: 2.3 | K22: 3.2 | L22: 1.8 | M22: 2 | N22: 2
A23: CIENCIAS BIOLOGICAS | B23: LIC | D23: SOURE | E23: SOU | F23: 201113635 | G23: 94739 | H23: 2012 | I23: 30/11 A 03/12/2012 | J23: 3 | K23: 3.7 | L23: 2.2 | M23: 3 | N23: 3
A24: CIENCIAS BIOLOGICAS | B24: LIC | D24: ALTAMIRA | E24: ALT | F24: 201201654 | G24: 96705 | H24: 2012 | I24: 04/11 A 07/11/2012 | J24: 3.6 | K24: 4.4 | L24: 4.3 | M24: 4 | N24: 3
... A26: AGRONOMIA | B26: BACH | D26: ALTAMIRA | E26: ALT | F26: 201201459 | G26: 96700 | H26: 2012 | I26: 07/11 A 10/11/12 | J26: 2.9 | K26: 3.5 | L26: 1.6 | M26: 3 | N26: 3
I27: Média | J27: =AVERAGE(J13:J26) -> 3.3071429 | K27: =AVERAGE(K13:K26) -> 3.9857143 | L27: =AVERAGE(L13:L26) -> 2.7642857 | M27: =AVERAGE(M13:M26) -> 3.2857143 | N27: =AVERAGE(N13:N26) -> 2.5714286

Sheet 2012 (GRAF)
A1: UNIVERSIDADE FEDERAL DO PARA
A2: PRÓ-REITORIA DE PLANEJAMENTO E DESENVOLVIMENTO INSTITUCIONAL
A3: DIRETORIA DE AVALIAÇÃO INSTITUCIONAL
A4: COORDENADORIA DE AUTOAVALIAÇÃO
B12: MÉDIA POR UND-ACAD
C13: D1 | D13: D2 | E13: D3
B14: ALT | C14: =AVERAGE('2012'!J15,'2012'!J21,'2012'!J24,'2012'!J26) -> 3.25 | D14: =AVERAGE('2012'!K15,'2012'!K21,'2012'!K24,'2012'!K26) -> 3.925 | E14: =AVERAGE('2012'!L15,'2012'!L21,'2012'!L24,'2012'!L26) -> 2.825
B15: CMT | C15: =AVERAGE('2012'!J14) -> 2.9 | D15: =AVERAGE('2012'!K14) -> 4.1 | E15: =AVERAGE('2012'!L14) -> 1.6
B16: CST | C16: =AVERAGE('2012'!J13) -> 2.7 | D16: =AVERAGE('2012'!K13) -> 3.9 | E16: =AVERAGE('2012'!L13) -> 2.6
B17: SOU | C17: =AVERAGE('2012'!J23) -> 3 | D17: =AVERAGE('2012'!K23) -> 3.7 | E17: =AVERAGE('2012'!L23) -> 2.2
B18: MRB | C18: =AVERAGE('2012'!J19) -> 3.1 | D18: =AVERAGE('2012'!K19) -> 4.1 | E18: =AVERAGE('2012'!L19) -> 3.3
B19: ILC | C19: =AVERAGE('2012'!J16) -> 3.5 | D19: =AVERAGE('2012'!K16) -> 3.4 | E19: =AVERAGE('2012'!L16) -> 3.6
B20: IG | C20: =(AVERAGE('2012'!J18)) -> 4.4 | D20: =(AVERAGE('2012'!K18)) -> 4.3 | E20: =(AVERAGE('2012'!L18)) -> 4.3
B21: ITEC | C21: =AVERAGE('2012'!J20) -> 5 | D21: =AVERAGE('2012'!K20) -> 5 | E21: =AVERAGE('2012'!L20) -> 4
B22: ICEN | C22: =AVERAGE('2012'!J22) -> 2.3 | D22: =AVERAGE('2012'!K22) -> 3.2 | E22: =AVERAGE('2012'!L22) -> 1.8
B23: ICB | C23: =AVERAGE('2012'!J25) -> 3.4 | D23: =AVERAGE('2012'!K25) -> 4.1 | E23: =AVERAGE('2012'!L25) -> 2.1
B24: IFCH | C24: =AVERAGE('2012'!J17) -> 3 | D24: =AVERAGE('2012'!K17) -> 4.3 | E24: =AVERAGE('2012'!L17) -> 1.9
A33: D1 - ORGANIZAÇÃO DIDÁTICO-PEDAGÓGICA - Fontes de Consulta: Plano de Desenvolvimento Institucional, Projeto Pedagógico do Curso, Relatório de Autoavaliação Institucional, Políticas Institucionais, Diretrizes Curriculares Nacionais, quando houver, Catálogo Nacional dos Cursos Superiores de Tecnologia, quando couber, Formulário Eletrônico preenchido pela IES no e-MEC.
A35: D2 - CORPO DOCENTE E TUTORIAL - Fontes de consulta: Projeto Pedagógico do Curso, Plano de Desenvolvimento Institucional, Políticas de Formação Docente, Formulário Eletrônico preenchido pela IES no e-MEC, Documentação Comprobatória e Catálogo Nacional dos Cursos Superiores de Tecnologia, quando couber.
A37: D3 - INFRAESTRUTURA - Fontes de Consulta: Projeto Pedagógico do Curso, Diretrizes Curriculares Nacionais, quando houver, Catálogo Nacional dos Cursos Superiores de Tecnologia, quando couber. Formulário Eletrônico preenchido pela IES no e-MEC e Documentação Comprobatória.

Sheet 2013
A1: UNIVERSIDADE FEDERAL DO PARA
A2: PRÓ-REITORIA DE PLANEJAMENTO E DESENVOLVIMENTO INSTITUCIONAL
A3: DIRETORIA DE AVALIAÇÃO INSTITUCIONAL
A4: COORDENADORIA DE AUTOAVALIAÇÃO
E10: MOSTRA O RELATÓRIO DA AVALIAÇÃO
A13: CURSO AVAL | B13: MOD | C13: COD-CURSO | D13: CAMPUS | E13: UND-ACAD | F13: PROC. Nº | G13: COD-AVAL | H13: ANO AVAL. | I13: PERIODO | J13: D1 | K13: D2 | L13: D3 | M13: CC | N13: AVAL
A14: QUÍMICA-EAD | B14: LIC | D14: POLO BUJARU | E14: ICEN | F14: 201113636 | G14: 96695 | H14: 2013 | I14: 24 A 270213 | J14: 3 | K14: 3.2 | L14: 3.2 | M14: 3 | N14: 2
A15: ENG. CIVIL | B15: BACH | D15: TUCURUÍ | E15: TUC | F15: 201204945 | G15: 97689 | H15: 2013 | I15: 25 A 280213 | J15: 3.2 | K15: 3.6 | L15: 3.1 | M15: 3 | N15: 3
A16: LETRAS-PORT-EAD | B16: LIC | D16: BELÉM | E16: ILC | F16: 201200143 | G16: 96388 | H16: 2013 | I16: 03 A 060313 | J16: 3.5 | K16: 4 | L16: 3.4 | M16: 4 | N16: 2
A17: EDUCAÇÃO CAMPO | B17: LIC | D17: MARABÁ | E17: MRB | F17: 201013329 | G17: 88618 | H17: 2013 | I17: 17 A 200313 | J17: 4 | K17: 4 | L17: 3 | M17: 4 | N17: 2
A18: ENG. PESCA | B18: BACH | D18: BRAGANÇA | E18: BRG | F18: 201008709 | G18: 84679 | H18: 2013 | I18: 03 A 060413 | J18: 4 | K18: 5 | L18: 1 | M18: 3 | N18: 3
A19: CIÊNCIAS NATURAIS | B19: LIC | D19: BELÉM | E19: ICEN | F19: 201112597 | G19: 98531 | H19: 2013 | I19: 17 A 200413 | J19: 3.1 | K19: 4.2 | L19: 4 | M19: 4 | N19: 3
A20: HISTÓRIA | B20: LIC | D20: BRAGANÇA | E20: BRG | F20: 201207762 | G20: 98031 | H20: 2013 | I20: 21 A 240413 | J20: 4.1 | K20: 4.8 | L20: 3.1 | M20: 4 | N20: 4
A21: ARTES VISUAIS | B21: LIC | D21: BELÉM | E21: ICA | F21: 201108850 | G21: 93690 | H21: 2013 | I21: 05 A 080513 | J21: 3.5 | K21: 4.6 | L21: 2.5 | M21: 4 | N21: 3
A22: CIÊNCIAS NATURAIS | B22: LIC | D22: BRAGANÇA | E22: BRG | F22: 201117382 | G22: 97990 | H22: 2013 | I22: 05 A 080513 | J22: 3.6 | K22: 3.5 | L22: 3.1 | M22: 3 | N22: 3
A23: ENG. ELÉTRICA | B23: BACH | D23: TUCURUÍ | E23: TUC | F23: 201206405 | G23: 98763 | H23: 2013 | I23: 05 A 080513 | J23: 3.8 | K23: 3.4 | L23: 3.4 | M23: 4 | N23: 3
A24: CIÊNCIAS NATURAIS | B24: LIC | D24: CAMETÁ | E24: CMT | F24: 201203940 | G24: 97999 | H24: 2013 | I24: 02 A 050613 | J24: 2.9 | K24: 3.4 | L24: 1.8 | M24: 3 | N24: 2
A25: BIOTECNOLOGIA | B25: BACH | D25: BELÉM | E25: ICB | F25: 201203362 | G25: 96504 | H25: 2013 | I25: 17 A 200713 | J25: 3.5 | K25: 3.9 | L25: 2.5 | M25: 3 | N25: 2
... A32: LETRAS | B32: LIC | D32: BREVES | E32: BRV | F32: 201216487 | G32: 99223 | H32: 2013 | I32: 02 A 051013 | J32: 3.1 | K32: 3.6 | L32: 2.4 | M32: 3 | N32: 2
A33: CIÊNCIAS NATURAIS | B33: LIC | D33: MARABÁ | E33: MRB | H33: 2013 | I33: 30 A 021113 | J33: 2.6 | K33: 4.1 | L33: 2.1 | M33: 3 | N33: 3 | O33: Não tem disponível
A34: SEDE-EAD | D34: BELÉM (SEDE) | E34: UFPA-EAD | F34: 201203603 | G34: 100904 | H34: 2013 | I34: 22 A 261013 | J34: 5 | K34: 2 | L34: 4 | M34: 3 | N34: 5
I35: Média | J35: =AVERAGE(J14:J34) -> 3.5142857 | K35: =AVERAGE(K14:K34) -> 3.9095238 | L35: =AVERAGE(L14:L34) -> 2.8619048 | M35: =AVERAGE(M14:M34) -> 3.4285714 | N35: =AVERAGE(N14:N34) -> 2.6666667

Sheet 2013 (GRAF)
A1: UNIVERSIDADE FEDERAL DO PARA
A2: PRÓ-REITORIA DE PLANEJAMENTO E DESENVOLVIMENTO INSTITUCIONAL
A3: DIRETORIA DE AVALIAÇÃO INSTITUCIONAL
A4: COORDENADORIA DE AUTOAVALIAÇÃO
B13: MÉDIA POR UND-ACAD
B14: UND-ACAD | C14: D1 | D14: D2 | E14: D3
B15: ABT | C15: =AVERAGE('2013'!J26) -> 2.5 | D15: =AVERAGE('2013'!K26) -> 3.7 | E15: =AVERAGE('2013'!L26) -> 2.8
B16: ALT | C16: =AVERAGE('2013'!J27) -> 4 | D16: =AVERAGE('2013'!K27) -> 4 | E16: =AVERAGE('2013'!L27) -> 2
B17: BRG | C17: =AVERAGE('2013'!J18,'2013'!J20,'2013'!J22,'2013'!J29) -> 3.95 | D17: =AVERAGE('2013'!K18,'2013'!K20,'2013'!K22,'2013'!K29) -> 4.475 | E17: =AVERAGE('2013'!L18,'2013'!L20,'2013'!L22,'2013'!L29) -> 2.625
B18: BRV | C18: =AVERAGE('2013'!J32) -> 3.1 | D18: =AVERAGE('2013'!K32) -> 3.6 | E18: =AVERAGE('2013'!L32) -> 2.4
B19: CMT | C19: =AVERAGE('2013'!J24,'2013'!J31) -> 2.95 | D19: =AVERAGE('2013'!K24,'2013'!K31) -> 3.7 | E19: =AVERAGE('2013'!L24,'2013'!L31) -> 2.1
B20: ICA | C20: =AVERAGE('2013'!J21) -> 3.5 | D20: =AVERAGE('2013'!K21) -> 4.6 | E20: =AVERAGE('2013'!L21) -> 2.5
B21: ICB | C21: =AVERAGE('2013'!J25) -> 3.5 | D21: =AVERAGE('2013'!K25) -> 3.9 | E21: =AVERAGE('2013'!L25) -> 2.5
B22: ICEN | C22: =AVERAGE('2013'!J14,'2013'!J19) -> 3.05 | D22: =AVERAGE('2013'!K14,'2013'!K19) -> 3.7 | E22: =AVERAGE('2013'!L14,'2013'!L19) -> 3.6
B23: ILC | C23: =AVERAGE('2013'!M16,'2013'!J30) -> 3.9 | D23: =AVERAGE('2013'!N16,'2013'!K30) -> 3.1 | E23: =AVERAGE('2013'!O16,'2013'!L30) -> 3.6
B24: ITEC | C24: =AVERAGE('2013'!J28) -> 3.5 | D24: =AVERAGE('2013'!K28) -> 4.3 | E24: =AVERAGE('2013'!L28) -> 3.4
B25: MRB | C25: =AVERAGE('2013'!J17,'2013'!J33) -> 3.3 | D25: =AVERAGE('2013'!K17,'2013'!K33) -> 4.05 | E25: =AVERAGE('2013'!L17,'2013'!L33) -> 2.55
B26: TUC | C26: =AVERAGE('2013'!J34) -> 5 | D26: 3.5 | E26: 3.25
B27: UFPA-EAD | C27: =AVERAGE('2013'!J34) -> 5 | D27: =AVERAGE('2013'!K34) -> 2 | E27: =AVERAGE('2013'!L34) -> 4
A36: D1 - ORGANIZAÇÃO DIDÁTICO-PEDAGÓGICA - Fontes de Consulta: Plano de Desenvolvimento Institucional, Projeto Pedagógico do Curso, Relatório de Autoavaliação Institucional, Políticas Institucionais, Diretrizes Curriculares Nacionais, quando houver, Catálogo Nacional dos Cursos Superiores de Tecnologia, quando couber, Formulário Eletrônico preenchido pela IES no e-MEC.
A38: D2 - CORPO DOCENTE E TUTORIAL - Fontes de consulta: Projeto Pedagógico do Curso, Plano de Desenvolvimento Institucional, Políticas de Formação Docente, Formulário Eletrônico preenchido pela IES no e-MEC, Documentação Comprobatória e Catálogo Nacional dos Cursos Superiores de Tecnologia, quando couber.
A40: D3 - INFRAESTRUTURA - Fontes de Consulta: Projeto Pedagógico do Curso, Diretrizes Curriculares Nacionais, quando houver, Catálogo Nacional dos Cursos Superiores de Tecnologia, quando couber. Formulário Eletrônico preenchido pela IES no e-MEC e Documentação Comprobatória.

Sheet 2014
A1: UNIVERSIDADE FEDERAL DO PARA
A2: PRÓ-REITORIA DE PLANEJAMENTO E DESENVOLVIMENTO INSTITUCIONAL
A3: DIRETORIA DE AVALIAÇÃO INSTITUCIONAL
A4: COORDENADORIA DE AUTOAVALIAÇÃO
E10: MOSTRA O RELATÓRIO DA AVALIAÇÃO
A13: CURSO | B13: MOD | C13: COD-CURSO | D13: CAMPUS | E13: UND-ACAD | F13: PROC. Nº | G13: COD-AVAL | H13: ANO AVAL. | I13: PERIODO | J13: D1 | K13: D2 | L13: D3 | M13: CC | N13: AVAL
A14: ENG.MATERIAIS | B14: BACH | D14: ANANINDEUA | E14: ANA | F14: 201302215 | G14: 104523 | H14: 2014 | I14: 05 A 08/02/14 | J14: 3.4 | K14: 4 | L14: 2.9 | M14: 3 | N14: 3
A15: EAD | B15: - | D15: CAPANEMA | E15: UFPA | F15: 201203603 | G15: 100906 | H15: 2014 | I15: 16 A 20/02/14 | J15: 2 | K15: 2 | L15: 3 | M15: 2 | N15: 2
A16: ENG. INDUSTRIAL | B16: BACH | D16: ABAETETUBA | E16: ABT | F16: 201013883 | G16: 88057 | H16: 2014 | I16: 09 A 12/02/14 | J16: 3 | K16: 4 | L16: 3 | M16: 3 | N16: 2
A17: INTER-DISCIPLINAR INTEGRADA EM EDUCAÇÃO, CIÊNCIAS, MATEMÁTICA E LINGUAGEM | B17: LIC | D17: IEMCI-BELÉM | E17: IEMCI | F17: 201203179 | G17: 98943 | H17: 2014 | I17: 09 A 12/02/14 | J17: 4.1 | K17: 4.8 | L17: 3.4 | M17: 4 | N17: 2
A18: ADM.PÚBLICA - EAD | B18: BACH | D18: BELÉM-EAD | E18: ICSA | F18: 201305868 | G18: 100591 | H18: 2014 | I18: 09 A 12/03/14 | J18: 4.4 | K18: 4.5 | L18: 4.1 | M18: 4 | N18: 4
A19: AGRONOMIA | B19: BACH | D19: CAMETÁ | E19: CMT | F19: 201413846 | G19: 116285 | H19: 2014 | I19: 14 A 17/12/2014 | J19: 3.2 | K19: 4.4 | L19: 2.3 | M19: 3 | N19: 2
A20: LETRAS-INGLÊS | B20: LIC | D20: CAMETÁ | E20: CMT | F20: 201208072 | G20: 100926 | H20: 2014 | I20: 09 A 12/03/14 | J20: 4 | K20: 4.5 | L20: 2.8 | M20: 4 | N20: 4
A21: MUSEOLOGIA | B21: BACH | D21: BELÉM | E21: ICA | F21: 201203361 | G21: 108398 | H21: 2014 | I21: 27 A 30/04/2014 | J21: 3.8 | K21: 4.2 | L21: 2.6 | M21: 4 | N21: 4
A22: FISIOTERAPIA | B22: BACH | D22: BELÉM | E22: ICS | F22: 201300118 | G22: 108467 | H22: 2014 | I22: 27 A 30/04/2014 | J22: 4.3 | K22: 4.1 | L22: 2.5 | M22: 4 | N22: 4
A23: MEDICINA | B23: BACH | D23: BELÉM | E23: ICS | F23: 201101339 | G23: 109100 | H23: 2014 | I23: 11 A 14/05/2014 | J23: 3.3 | K23: 4.1 | L23: 3.3 | M23: 4 | N23: 3
A24: ETNODESENVOLVIMENTO | B24: BACH | D24: ALTAMIRA | E24: ALT | F24: 201200573 | G24: 101607 | H24: 2014 | I24: 21 A 24/05/2014 | J24: 3.4 | K24: 3.4 | L24: 2.8 | M24: 3 | N24: 1
A25: DANÇA | B25: LIC | D25: BELÉM | E25: ICA | F25: 201007991 | G25: 85886 | H25: 2014 | I25: 25 A 28/05/2014 | J25: 5 | K25: 5 | L25: 4 | M25: 5 | N25: 4
... A29: GEOFÍSICA | B29: BACH | D29: BELÉM | E29: IG | F29: 201350666 | G29: 104113 | H29: 2014 | I29: 21 a 24/09/2014 | J29: 3.9 | K29: 4.2 | L29: 3.3 | M29: 4 | N29: 3
A30: GEOGRAFIA | B30: LIC | D30: BELÉM | E30: IFCH | I30: 30/11 A 03/12/2014 | J30: 3.1 | K30: 4 | L30: 3.8 | M30: 4 | N30: 3
A31: LETRAS INGLES | B31: LIC | D31: SOURE | E31: SOU | F31: 201357622 | G31: 107640 | H31: 2014 | I31: 24 a 27/09/2014 | J31: 3 | K31: 3 | L31: 1.9 | M31: 3 | N31: 3
A32: COM.SOC-JORNALISMO | B32: BACH | D32: BELEM | E32: ILC | F32: 201360675 | G32: 115517 | H32: 2014 | I32: 14 A 17/12/2014 | J32: 3.1 | K32: 4.4 | L32: 2.8 | M32: 3 | N32: 2
A33: DIREITO | B33: BACH | D33: BELÉM | E33: ICJ | F33: 201402776 | G33: 110014 | H33: 2014 | I33: 09 A 12/11/14 | J33: 3.1 | K33: 3.9 | L33: 2.8 | M33: 3 | N33: 2
A34: TERAPIA OCUPACIONAL | B34: BACH | D34: BELEM | E34: ICS | F34: 201357216 | G34: 107207 | H34: 2014 | I34: 23 A 26/11/2014 | J34: 3.3 | K34: 3.9 | L34: 2.7 | M34: 3 | N34: 3
A35: EAD - MARABA | B35: - | D35: MARABA | E35: MRB | F35: 201203603 | G35: 100907 | H35: 2014 | I35: 41737 | J35: 3 | K35: 3 | L35: 3 | M35: 3 | N35: 3
A36: EAD - Campus UFPA | B36: - | D36: BELÉM | E36: UFPA | F36: 201203603 | G36: 100905 | H36: 2014 | I36: 03 A 06/08/2014 | J36: 2 | K36: 2 | L36: 3 | M36: 3 | N36: 2
I37: Média | J37: =AVERAGE(J14:J36) -> 3.4347826 | K37: =AVERAGE(K14:K36) -> 3.9 | L37: =AVERAGE(L14:L36) -> 3.0565217 | M37: =AVERAGE(M14:M36) -> 3.4782609 | N37: =AVERAGE(N14:N36) -> 2.8695652

Sheet 2014 (GRAF)
A1: UNIVERSIDADE FEDERAL DO PARA
A2: PRÓ-REITORIA DE PLANEJAMENTO E DESENVOLVIMENTO INSTITUCIONAL
A3: DIRETORIA DE AVALIAÇÃO INSTITUCIONAL
A4: COORDENADORIA DE AUTOAVALIAÇÃO
C11: UND-ACAD | D11: D1 | E11: D2 | F11: D3
C12: ABT | D12: =AVERAGE('2014'!J27) -> 3.8 | E12: =AVERAGE('2014'!K27) -> 3.7 | F12: =AVERAGE('2014'!L27) -> 3.5
C13: ALT | D13: =AVERAGE('2014'!J24) -> 3.4 | E13: =AVERAGE('2014'!K24) -> 3.4 | F13: =AVERAGE('2014'!L24) -> 2.8
C14: ANA | D14: =AVERAGE('2014'!J14) -> 3.4 | E14: =AVERAGE('2014'!K14) -> 4 | F14: =AVERAGE('2014'!L14) -> 2.9
C15: CMT | D15: =AVERAGE('2014'!J19,'2014'!J20) -> 3.6 | E15: =AVERAGE('2014'!K19,'2014'!K20) -> 4.45 | F15: =AVERAGE('2014'!L19,'2014'!L20) -> 2.55
C16: CST | D16: =AVERAGE('2014'!J28) -> 3.5 | E16: =AVERAGE('2014'!K28) -> 4.9 | F16: =AVERAGE('2014'!L28) -> 4
C17: ICA | D17: =AVERAGE('2014'!J21,'2014'!J25) -> 4.4 | E17: =AVERAGE('2014'!K21,'2014'!K25) -> 4.6 | F17: =AVERAGE('2014'!L21,'2014'!L25) -> 3.3
C18: ICJ | D18: =AVERAGE('2014'!J33) -> 3.1 | E18: =AVERAGE('2014'!K33) -> 3.9 | F18: =AVERAGE('2014'!L33) -> 2.8
C19: ICS | D19: =AVERAGE('2014'!J22,'2014'!J23,'2014'!J34) -> 3.6333333 | E19: =AVERAGE('2014'!K22,'2014'!K23,'2014'!K34) -> 4.0333333 | F19: =AVERAGE('2014'!L22,'2014'!L23,'2014'!L34) -> 2.8333333
C20: ICSA | D20: =AVERAGE('2014'!J18) -> 4.4 | E20: =AVERAGE('2014'!K18) -> 4.5 | F20: =AVERAGE('2014'!L18) -> 4.1
C21: IEMCI | D21: =AVERAGE('2014'!J17) -> 4.1 | E21: =AVERAGE('2014'!K17) -> 4.8 | F21: =AVERAGE('2014'!L17) -> 3.4
C22: IFCH | D22: =AVERAGE('2014'!J30) -> 3.1 | E22: =AVERAGE('2014'!K30) -> 4 | F22: =AVERAGE('2014'!L30) -> 3.8
C23: IG | D23: =AVERAGE('2014'!J29) -> 3.9 | E23: =AVERAGE('2014'!K29) -> 4.2 | F23: =AVERAGE('2014'!L29) -> 3.3
C24: ILC | D24: =AVERAGE('2014'!J26,'2014'!J32) -> 3.2 | E24: =AVERAGE('2014'!K26,'2014'!K32) -> 4.05 | F24: =AVERAGE('2014'!L26,'2014'!L32) -> 2.8
C25: MRB | D25: =AVERAGE('2014'!J35) -> 3 | E25: =AVERAGE('2014'!K35) -> 3 | F25: =AVERAGE('2014'!L35) -> 3
C26: SOU | D26: =AVERAGE('2014'!J31) -> 3 | E26: =AVERAGE('2014'!K31) -> 3 | F26: =AVERAGE('2014'!L31) -> 1.9
C27: UFPA | D27: =AVERAGE('2014'!J15,'2014'!J36) -> 2 | E27: =AVERAGE('2014'!K15,'2014'!K36) -> 2 | F27: =AVERAGE('2014'!L15,'2014'!L36) -> 3
A39: D1 - ORGANIZAÇÃO DIDÁTICO-PEDAGÓGICA - Fontes de Consulta: Plano de Desenvolvimento Institucional, Projeto Pedagógico do Curso, Relatório de Autoavaliação Institucional, Políticas Institucionais, Diretrizes Curriculares Nacionais, quando houver, Catálogo Nacional dos Cursos Superiores de Tecnologia, quando couber, Formulário Eletrônico preenchido pela IES no e-MEC.
A41: D2 - CORPO DOCENTE E TUTORIAL - Fontes de consulta: Projeto Pedagógico do Curso, Plano de Desenvolvimento Institucional, Políticas de Formação Docente, Formulário Eletrônico preenchido pela IES no e-MEC, Documentação Comprobatória e Catálogo Nacional dos Cursos Superiores de Tecnologia, quando couber.
A43: D3 - INFRAESTRUTURA - Fontes de Consulta: Projeto Pedagógico do Curso, Diretrizes Curriculares Nacionais, quando houver, Catálogo Nacional dos Cursos Superiores de Tecnologia, quando couber. Formulário Eletrônico preenchido pela IES no e-MEC e Documentação Comprobatória.

Sheet 2015
D10: MOSTRA O RELATÓRIO DA AVALIAÇÃO
A14: CURSO | B14: MOD | C14: COD-CURSO | D14: CAMPUS | E14: UND-ACAD | F14: PROC. Nº | G14: COD-AVAL | H14: ANO AVAL. | I14: PERIODO | J14: D1 | K14: D2 | L14: D3 | M14: CC | N14: AVAL
A15: SISTEMA DE INFORMAÇÃO | B15: BACH | D15: CAMETÁ | E15: CMT | F15: 201356894 | G15: 107052 | H15: 2015 | I15: 08 A 11/02/2015 | J15: 3.5 | K15: 4 | L15: 2.9 | M15: 3 | N15: 2
A16: ARTES VISUAIS | B16: BACH | D16: BELÉM | E16: ICA | F16: 201350143 | G16: 104053 | H16: 2015 | I16: 22 A 25/02/2015 | J16: 4.1 | K16: 4.5 | L16: 3.8 | M16: 4 | N16: 3
A17: PRODUÇÃO MULTIMÍDIA | B17: TEC | D17: BELÉM | E17: ICA | F17: 201403408 | G17: 110470 | H17: 2015 | I17: 12 A 15/04/2015 | J17: 3.8 | K17: 4.4 | L17: 3.2 | M17: 4 | N17: 3
A18: COM.SOCIAL-PUB | B18: BACH | D18: BELÉM | E18: ILC | F18: 201407696 | G18: 112181 | H18: 2015 | I18: 03 A 06/05/2015 | J18: 3.4 | K18: 4.6 | L18: 2.8 | M18: 4 | N18: 3
A19: PEDAGOGIA | B19: LIC | D19: BREVES | E19: BRV | F19: 201216494 | G19: 99224 | H19: 2015 | I19: 21 a 24/06/2015 | J19: 4.1 | K19: 4.3 | L19: 3.5 | M19: 4 | N19: 3
A20: LETRAS - ESPANHOL | B20: LIC | D20: ABAETETUBA | E20: ABT | F20: 201357263 | G20: 107071 | H20: 2015 | I20: 02 A 05/08/015 | J20: 3.5 | K20: 2.3 | L20: 3.1 | M20: 3 | N20: 4
A21: LETRAS - ESPANHOL | B21: LIC | D21: CASTANHAL | E21: CST | F21: 201357270 | G21: 107115 | H21: 2015 | I21: 16 a 19/09/015 | J21: 3.8 | K21: 4.6 | L21: 3.6 | M21: 4 | N21: 3
A22: BIBLIOTECONOMIA | B22: BACH | D22: BELÉM | E22: ICSA | F22: 201410728 | G22: 119796 | H22: 2015 | I22: 18 A 21/11/015 | J22: 3.4 | K22: 4.6 | L22: 2.7 | M22: 4 | N22: 1
I23: Média | J23: =AVERAGE(J15:J22) -> 3.7 | K23: =AVERAGE(K15:K22) -> 4.1625 | L23: =AVERAGE(L15:L22) -> 3.2 | M23: =AVERAGE(M15:M22) -> 3.75 | N23: =AVERAGE(N15:N22) -> 2.75

Sheet 2015 (GRAF)
A1: UNIVERSIDADE FEDERAL DO PARA
A2: PRÓ-REITORIA DE PLANEJAMENTO E DESENVOLVIMENTO INSTITUCIONAL
A3: DIRETORIA DE AVALIAÇÃO INSTITUCIONAL
A4: COORDENADORIA DE AUTOAVALIAÇÃO
C11: UND ACAD | D11: D1 | E11: D2 | F11: D3
C12: ABT | D12: =AVERAGE('2015'!J20) -> 3.5 | E12: =AVERAGE('2015'!K20) -> 2.3 | F12: =AVERAGE('2015'!L20) -> 3.1
C13: BRV | D13: =AVERAGE('2015'!J19) -> 4.1 | E13: =AVERAGE('2015'!K19) -> 4.3 | F13: =AVERAGE('2015'!L19) -> 3.5
C14: CST | D14: =AVERAGE('2015'!J21) -> 3.8 | E14: =AVERAGE('2015'!K21) -> 4.6 | F14: =AVERAGE('2015'!L21) -> 3.6
C15: CMT | D15: =AVERAGE('2015'!J15) -> 3.5 | E15: =AVERAGE('2015'!K15) -> 4 | F15: =AVERAGE('2015'!L15) -> 2.9
C16: ICA | D16: =AVERAGE('2015'!J16,'2015'!J17) -> 3.95 | E16: =AVERAGE('2015'!K16,'2015'!K17) -> 4.45 | F16: =AVERAGE('2015'!L16,'2015'!L17) -> 3.5
C17: ICSA | D17: =AVERAGE('2015'!J22) -> 3.4 | E17: =AVERAGE('2015'!K22) -> 4.6 | F17: =AVERAGE('2015'!L22) -> 2.7
C18: ILC | D18: =AVERAGE('2015'!J18) -> 3.4 | E18: =AVERAGE('2015'!K18) -> 4.6 | F18: =AVERAGE('2015'!L18) -> 2.8
A34: D1 - ORGANIZAÇÃO DIDÁTICO-PEDAGÓGICA - Fontes de Consulta: Plano de Desenvolvimento Institucional, Projeto Pedagógico do Curso, Relatório de Autoavaliação Institucional, Políticas Institucionais, Diretrizes Curriculares Nacionais, quando houver, Catálogo Nacional dos Cursos Superiores de Tecnologia, quando couber, Formulário Eletrônico preenchido pela IES no e-MEC.
A36: D2 - CORPO DOCENTE E TUTORIAL - Fontes de consulta: Projeto Pedagógico do Curso, Plano de Desenvolvimento Institucional, Políticas de Formação Docente, Formulário Eletrônico preenchido pela IES no e-MEC, Documentação Comprobatória e Catálogo Nacional dos Cursos Superiores de Tecnologia, quando couber.
A38: D3 - INFRAESTRUTURA - Fontes de Consulta: Projeto Pedagógico do Curso, Diretrizes Curriculares Nacionais, quando houver, Catálogo Nacional dos Cursos Superiores de Tecnologia, quando couber. Formulário Eletrônico preenchido pela IES no e-MEC e Documentação Comprobatória.

Sheet 2016
A1: UNIVERSIDADE FEDERAL DO PARA
A2: PRÓ-REITORIA DE PLANEJAMENTO E DESENVOLVIMENTO INSTITUCIONAL
A3: DIRETORIA DE AVALIAÇÃO INSTITUCIONAL
A4: COORDENADORIA DE AUTOAVALIAÇÃO
E10: MOSTRA O RELATÓRIO DA AVALIAÇÃO
A13: CURSO | B13: MOD | C13: COD-CURSO | D13: CAMPUS | E13: UND-ACAD | F13: PROC. Nº | G13: COD-AVAL | H13: ANO AVAL. | I13: PERÍODO | J13: D1 | K13: D2 | L13: D3 | M13: CC | N13: AVAL
A14: ADMINISTRAÇÃO | B14: BACH | C14: 11989 | D14: BELÉM | E14: ICSA | F14: 201410961 | G14: 120548 | H14: 2016 | I14: 21 A 24/02 | J14: 3.2 | K14: 4.3 | L14: 3.1 | M14: 4 | N14: 3
A15: EDUCAÇÃO DO CAMPO | B15: LIC | C15: 1134445 | D15: ABAETETUBA | E15: ABT | F15: 201208909 | G15: 99807 | H15: 2016 | I15: 28/02 A 02/03 | J15: 4.3 | K15: 4.8 | L15: 4 | M15: 4 | N15: 3
A16: GEOGRAFIA | B16: LIC | C16: 1194057 | D16: CAMETÁ | E16: CMT | F16: 201501047 | G16: 123420 | H16: 2016 | I16: 09/03 A 12/03 | J16: 3.1 | K16: 4.1 | L16: 1.7 | M16: 3 | N16: 2
A17: CINEMA E AUDIOVISUAL | B17: TEC | C17: 1148597 | D17: BELÉM | E17: ICA | F17: 201207562 | G17: 99568 | H17: 2016 | I17: 03 A 03/04 | J17: 3.1 | K17: 3.8 | L17: 3.4 | M17: 3 | N17: 3
A18: GEOGRAFIA | B18: BACH | C18: 311991 | D18: BELÉM | E18: IFCH | F18: 201217042 | G18: 125503 | H18: 2016 | I18: 03 A 06/08/16 | J18: 3.4 | K18: 4.2 | L18: 2.5 | M18: 3 | N18: 3
A19: AGRONOMIA | B19: BACH | C19: 53101 | D19: ALTAMIRA | E19: ALT | F19: 201418317 | G19: 125528 | H19: 2016 | I19: 05 a 08/10/16 | J19: 3.1 | K19: 3.8 | L19: 2.3 | M19: 3 | N19: 3
A20: ENG. TELECOMUNICAÇÕES | B20: BACH | C20: 1179144 | D20: BELÉM | E20: ITEC | F20: 201413841 | G20: 117136 | H20: 2016 | I20: 30/11 A 03/12 | J20: 2.9 | K20: 4.4 | L20: 2.5 | M20: 3 | N20: 2
A21: GEOPROCESSAMENTO | B21: TEC | C21: 1299461 | D21: ANANINDEUA | E21: ANA | F21: 201602247 | G21: 127685 | H21: 2016 | I21: 11 A 14/12 | J21: 3.8 | K21: 4.1 | L21: 3.2 | M21: 4 | N21: 3
I22: Média | J22: =AVERAGE(J14:J21) -> 3.3625 | K22: =AVERAGE(K14:K21) -> 4.1875 | L22: =AVERAGE(L14:L21) -> 2.8375 | M22: =AVERAGE(M14:M21) -> 3.375 | N22: =AVERAGE(N14:N21) -> 2.75

Sheet 2016 (GRAF)
A1: UNIVERSIDADE FEDERAL DO PARA
A2: PRÓ-REITORIA DE PLANEJAMENTO E DESENVOLVIMENTO INSTITUCIONAL
A3: DIRETORIA DE AVALIAÇÃO INSTITUCIONAL
A4: COORDENADORIA DE AUTOAVALIAÇÃO
E12: D1 | F12: D2 | G12: D3
D13: ABT | E13: =AVERAGE('2016'!J15) -> 4.3 | F13: =AVERAGE('2016'!K15) -> 4.8 | G13: =AVERAGE('2016'!L15) -> 4
D14: ALT | E14: =AVERAGE('2016'!J19) -> 3.1 | F14: =AVERAGE('2016'!K19) -> 3.8 | G14: =AVERAGE('2016'!L19) -> 2.3
D15: ANA | E15: =AVERAGE('2016'!J21) -> 3.8 | F15: =AVERAGE('2016'!K21) -> 4.1 | G15: =AVERAGE('2016'!L21) -> 3.2
D16: CMT | E16: =AVERAGE('2016'!J16) -> 3.1 | F16: =AVERAGE('2016'!K16) -> 4.1 | G16: =AVERAGE('2016'!L16) -> 1.7
D17: ICA | E17: =AVERAGE('2016'!J17) -> 3.1 | F17: 3.8 | G17: 3.4
D18: ICSA | E18: 3.2 | F18: 3.2 | G18: 3.2
D19: IFCH | E19: =AVERAGE('2016'!J18) -> 3.4 | F19: =AVERAGE('2016'!K18) -> 4.2 | G19: =AVERAGE('2016'!L18) -> 2.5
D20: ITEC | E20: =AVERAGE('2016'!J20) -> 2.9 | F20: =AVERAGE('2016'!K20) -> 4.4 | G20: =AVERAGE('2016'!L20) -> 2.5
A34: D1 - ORGANIZAÇÃO DIDÁTICO-PEDAGÓGICA - Fontes de Consulta: Plano de Desenvolvimento Institucional, Projeto Pedagógico do Curso, Relatório de Autoavaliação Institucional, Políticas Institucionais, Diretrizes Curriculares Nacionais, quando houver, Catálogo Nacional dos Cursos Superiores de Tecnologia, quando couber, Formulário Eletrônico preenchido pela IES no e-MEC.
A36: D2 - CORPO DOCENTE E TUTORIAL - Fontes de consulta: Projeto Pedagógico do Curso, Plano de Desenvolvimento Institucional, Políticas de Formação Docente, Formulário Eletrônico preenchido pela IES no e-MEC, Documentação Comprobatória e Catálogo Nacional dos Cursos Superiores de Tecnologia, quando couber.
A38: D3 - INFRAESTRUTURA - Fontes de Consulta: Projeto Pedagógico do Curso, Diretrizes Curriculares Nacionais, quando houver, Catálogo Nacional dos Cursos Superiores de Tecnologia, quando couber. Formulário Eletrônico preenchido pela IES no e-MEC e Documentação Comprobatória.

Sheet 2017
B1: UNIVERSIDADE FEDERAL DO PARA
B2: PRÓ-REITORIA DE PLANEJAMENTO E DESENVOLVIMENTO INSTITUCIONAL
B3: DIRETORIA DE AVALIAÇÃO INSTITUCIONAL
B4: COORDENADORIA DE AUTOAVALIAÇÃO
D10: MOSTRA O RELATÓRIO DA AVALIAÇÃO | J10: RELATÓRIO PÓS PROT. COMP.
B13: CURSO | C13: MOD | D13: COD-CURSO | E13: CAMPUS | F13: UND-ACAD | G13: PROC. Nº | H13: COD-AVAL | I13: ANO AVAL. | J13: INICIO | K13: D1 | L13: D2 | M13: D3 | N13: CC | O13: AVAL
B14: FÍSICA - EAD | C14: LIC | D14: 1202639 | E14: Belém | F14: ICEN | G14: 201505783 | H14: 127391 | I14: 2017 | J14: 42830 | K14: 3.2 | L14: 3.8 | M14: 3.5 | N14: 3 | O14: 4
B15: ARQUIVOLOGIA | C15: BACH | D15: 1179143 | E15: Belém | F15: ICSA | G15: 201413605 | H15: 116261 | I15: 2017 | J15: 42834 | K15: 4 | L15: 4.7 | M15: 2.5 | N15: 4 | O15: 4
B16: LETRAS INGLES | C16: LIC | D16: 114877 | E16: Altamira | F16: ALT | G16: 201207537 | H16: 123732 | I16: 2017 | J16: 42858 | K16: 3.9 | L16: 4.6 | M16: 3.4 | N16: 4 | O16: 4
B17: LETRAS PORTUGUES | C17: LIC | D17: 114876 | E17: Altamira | F17: ALT | G17: 201201183 | H17: 123509 | I17: 2017 | J17: 42865 | K17: 3.8 | L17: 4.4 | M17: 3.8 | N17: 4 | O17: 3
B18: LETRAS INGLES | C18: LIC | D18: 95652 | E18: Soure | F18: SOU | G18: 201357622 | H18: 125702 | I18: 2017 | J18: 42872 | K18: 3.6 | L18: 4.7 | M18: 3.6 | N18: 4 | O18: 4
B19: AGRONOMIA | C19: BACH | D19: 1179151 | E19: Cametá | F19: CMT | G19: 201413846 | H19: 130974 | I19: 2017 | J19: 42890 | K19: 3.5 | L19: 3.6 | M19: 3.4 | N19: 4 | O19: 3
B20: GEOLOGIA | C20: BACH | D20: 12005 | E20: Belém | F20: IG | G20: 201617017 | H20: 135906 | I20: 2017 | J20: 42907 | K20: 4.5 | L20: 4.6 | M20: 4.2 | N20: 4 | O20: 5
B21: CIENCIAS NATURAIS | C21: LIC | E21: Bragança | F21: BRG | G21: 201616997 | H21: 135902 | I21: 2017 | J21: 42946 | K21: 3.6 | L21: 3.8 | M21: 3.1 | N21: 4 | O21: 3
B22: CIENCIAS NATURAIS | C22: LIC | E22: Belém | F22: ICEN | G22: 201616942 | H22: 135897 | I22: 2017 | J22: 42949 | K22: 3.3 | L22: 3.9 | M22: 3.3 | N22: 3 | O22: 3
B23: ETNODESENVOLVIMENTO | C23: BACH | E23: Altamira | F23: ALT | G23: 201501042 | H23: 123734 | I23: 2017 | J23: 42949 | K23: 3.2 | L23: 4.8 | M23: 2.9 | N23: 4 | O23: 3
B24: CIENCIA E TECNOLOGIA | C24: BACH | E24: Ananindeua | F24: ANA | G24: 201506093 | H24: 124705 | I24: 2017 | J24: 42953 | K24: 2.5 | L24: 3.9 | M24: 2.5 | N24: 3 | O24: 2
B25: EDUCAÇÃO DO CAMPO | C25: LIC | E25: Cametá | F25: CMT | G25: 201607682 | H25: 130677 | I25: 2017 | J25: 42953 | K25: 3.6 | L25: 4.3 | M25: 2.6 | N25: 4 | O25: 4
B26: QUIMICA INDUSTRIAL | C26: BACH | E26: Belém | F26: ICEN | G26: 201616945 | H26: 135898 | I26: 2017 | J26: 42963 | K26: 2.4 | L26: 3.5 | M26: 2.3 | N26: 3 | O26: 2
B27: MEDICINA VETERINARIA | C27: BACH | E27: Castanhal | F27: IMV | G27: 201503693 | H27: 132597 | I27: 2017 | J27: 42963 | K27: 3 | L27: 4.1 | M27: 3.3 | N27: 3 | O27: 2
B28: FISICA | C28: LIC | E28: Abaetetuba | F28: ABT | G28: 201617002 | H28: 136961 | I28: 2017 | J28: 42995 | K28: 4.1 | L28: 3.9 | M28: 3.8 | N28: 4 | O28: 3
B29: ENG. SANITARIA | C29: BACH | E29: Tucuruí | F29: TUC | G29: 201602245 | H29: 127683 | I29: 2017 | J29: 42995 | K29: 3.7 | L29: 4 | M29: 3.1 | N29: 4 | O29: 3
B30: MATEMATICA | C30: LIC | E30: Cameta | F30: CMT | G30: 201616763 | H30: 137891 | I30: 2017 | J30: 42998 | K30: 2.9 | L30: 3.8 | M30: 3 | N30: 3 | O30: 3
B31: ETNODESENVOLVIMENTO | C31: LIC | E31: Altamira | F31: ALT | G31: 201501043 | H31: 123735 | I31: 2017 | J31: 43005 | K31: 4.2 | L31: 4.4 | M31: 3.1 | N31: 4 | O31: 3
B32: Eng. Biomédica | C32: BACH | E32: Belém | F32: ITEC | G32: 201505762 | H32: 124704 | I32: 2017 | J32: 43023 | K32: 4.1 | L32: 3.8 | M32: 4.2 | N32: 4 | O32: 2
... B36: Eng. Ferroviária | C36: BACH | E36: Belém | F36: ITEC | G36: 201607684 | H36: 130689 | I36: 2017 | J36: 43068 | K36: 3.3 | L36: 4.3 | M36: 2.6 | N36: 3 | O36: 3
J37: Média | K37: =AVERAGE(K14:K36) -> 3.5782609 | L37: =AVERAGE(L14:L36) -> 4.1695652 | M37: =AVERAGE(M14:M36) -> 3.2826087 | N37: =AVERAGE(N14:N36) -> 3.6956522 | O37: =AVERAGE(O14:O36) -> 3.173913

Sheet 2017 (GRAF)
A1: UNIVERSIDADE FEDERAL DO PARA
A2: PRÓ-REITORIA DE PLANEJAMENTO E DESENVOLVIMENTO INSTITUCIONAL
A3: DIRETORIA DE AVALIAÇÃO INSTITUCIONAL
A4: COORDENADORIA DE AUTOAVALIAÇÃO
E14: UND-ACAD | F14: D1 | G14: D2 | H14: D3
E15: ABT | F15: =AVERAGE('2017'!K28,'2017'!K33) -> 3.9 | G15: =AVERAGE('2017'!L28,'2017'!L33) -> 3.95 | H15: =AVERAGE('2017'!M28,'2017'!M33) -> 3.65
E16: ALT | F16: =AVERAGE('2017'!K16,'2017'!K17,'2017'!K23,'2017'!K31) -> 3.775 | G16: =AVERAGE('2017'!L16,'2017'!L17,'2017'!L23,'2017'!L31) -> 4.55 | H16: =AVERAGE('2017'!M16,'2017'!M17,'2017'!M23,'2017'!M31) -> 3.3
E17: ANA | F17: =AVERAGE('2017'!K24) -> 2.5 | G17: =AVERAGE('2017'!L24) -> 3.9 | H17: =AVERAGE('2017'!M24) -> 2.5
E18: BRG | F18: =AVERAGE('2017'!K21,'2017'!K34) -> 4 | G18: =AVERAGE('2017'!L21,'2017'!L34) -> 4.15 | H18: =AVERAGE('2017'!M21,'2017'!M34) -> 3.45
E19: CMT | F19: =AVERAGE('2017'!K19,'2017'!K25,'2017'!K30) -> 3.3333333 | G19: =AVERAGE('2017'!L19,'2017'!L25,'2017'!L30) -> 3.9 | H19: =AVERAGE('2017'!M19,'2017'!M25,'2017'!M30) -> 3
E20: ICEN | F20: =AVERAGE('2017'!K14,'2017'!K22,'2017'!K26) -> 2.9666667 | G20: =AVERAGE('2017'!L14,'2017'!L22,'2017'!L26) -> 3.7333333 | H20: =AVERAGE('2017'!M14,'2017'!M22,'2017'!M26) -> 3.0333333
E21: ICSA | F21: =AVERAGE('2017'!K15) -> 4 | G21: =AVERAGE('2017'!L15) -> 4.7 | H21: =AVERAGE('2017'!M15) -> 2.5
E22: IG | F22: =AVERAGE('2017'!K20,'2017'!K35) -> 4.15 | G22: =AVERAGE('2017'!L20,'2017'!L35) -> 4.55 | H22: =AVERAGE('2017'!M20,'2017'!M35) -> 4.1
E23: IMV | F23: =AVERAGE('2017'!K27) -> 3 | G23: =AVERAGE('2017'!L27) -> 4.1 | H23: =AVERAGE('2017'!M27) -> 3.3
E24: ITEC | F24: =AVERAGE('2017'!K32,'2017'!K36) -> 3.7 | G24: =AVERAGE('2017'!L32,'2017'!L36) -> 4.05 | H24: =AVERAGE('2017'!M32,'2017'!M36) -> 3.4
E25: SOU | F25: =AVERAGE('2017'!K18) -> 3.6 | G25: =AVERAGE('2017'!L18) -> 4.7 | H25: =AVERAGE('2017'!M18) -> 3.6
E26: TUC | F26: =AVERAGE('2017'!K29) -> 3.7 | G26: =AVERAGE('2017'!L29) -> 4 | H26: =AVERAGE('2017'!M29) -> 3.1
A40: D1 - ORGANIZAÇÃO DIDÁTICO-PEDAGÓGICA - Fontes de Consulta: Plano de Desenvolvimento Institucional, Projeto Pedagógico do Curso, Relatório de Autoavaliação Institucional, Políticas Institucionais, Diretrizes Curriculares Nacionais, quando houver, Catálogo Nacional dos Cursos Superiores de Tecnologia, quando couber, Formulário Eletrônico preenchido pela IES no e-MEC.
A42: D2 - CORPO DOCENTE E TUTORIAL - Fontes de consulta: Projeto Pedagógico do Curso, Plano de Desenvolvimento Institucional, Políticas de Formação Docente, Formulário Eletrônico preenchido pela IES no e-MEC, Documentação Comprobatória e Catálogo Nacional dos Cursos Superiores de Tecnologia, quando couber.
A44: D3 - INFRAESTRUTURA - Fontes de Consulta: Projeto Pedagógico do Curso, Diretrizes Curriculares Nacionais, quando houver, Catálogo Nacional dos Cursos Superiores de Tecnologia, quando couber. Formulário Eletrônico preenchido pela IES no e-MEC e Documentação Comprobatória.

Sheet 2018
A1: UNIVERSIDADE FEDERAL DO PARA
A2: PRÓ-REITORIA DE PLANEJAMENTO E DESENVOLVIMENTO INSTITUCIONAL
A3: DIRETORIA DE AVALIAÇÃO INSTITUCIONAL
A4: COORDENADORIA DE AUTOAVALIAÇÃO
D10: MOSTRA O RELATÓRIO DA AVALIAÇÃO
A13: Curso | B13: MOD | C13: COD_CURSO | D13: Campus | E13: UND-ACAD | F13: Nº PROC | G13: Nº AVAL. | H13: ANO_AVAL | I13: INICIO | J13: D1 | K13: D2 | L13: D3 | M13: CC | N13: AVAL
A14: Ciências Naturais | B14: LIC | D14: Breves | E14: BRV | F14: 201505783 | G14: 127391 | H14: 2018 | I14: 18/02 | J14: 4.19 | K14: 4.42 | L14: 3.88 | M14: 4 | N14: 3
A15: Eng. da Computação | B15: BACH | D15: Tucuruí | E15: TUC | F15: 201413605 | G15: 116261 | H15: 2018 | I15: 28/02 | J15: 3.6 | K15: 4.46 | L15: 2.9 | M15: 4 | N15: 3
A16: Farmácia (Bach) | B16: BACH | D16: Belém | E16: ICS | F16: 201207537 | G16: 123732 | H16: 2018 | I16: 18/03 | J16: 4.39 | K16: 4.75 | L16: 3.81 | M16: 4 | N16: 3
A17: Fisioterapia | B17: BACH | D17: Belém | E17: ICS | F17: 201201183 | G17: 123509 | H17: 2018 | I17: 25/03 | J17: 4.59 | K17: 4.91 | L17: 4.77 | M17: 5 | N17: 4
A18: Eng. de Pesca | B18: BACH | D18: Bragança | E18: BRG | F18: 201413846 | G18: 130974 | H18: 2018 | I18: 08/04 | J18: 4.47 | K18: 4.64 | L18: 3.91 | M18: 4 | N18: 5
A19: Eng. da Computação | B19: BACH | D19: Castanhal | E19: CST | F19: 201617017 | G19: 135906 | H19: 2018 | I19: 18/04 | J19: 3.65 | K19: 4.14 | L19: 3.4 | M19: 4 | N19: 3
A20: Educação do Campo | B20: LIC | D20: Altamira | E20: ALT | F20: 201616997 | G20: 135902 | H20: 2018 | I20: 22/04 | J20: 4.75 | K20: 5 | L20: 4.22 | M20: 5 | N20: 4
A21: Musica | B21: LIC | D21: Belém | E21: ICA | F21: 201616942 | G21: 135897 | H21: 2018 | I21: 09/05 | J21: 4.4 | K21: 4.17 | L21: 4 | M21: 4 | N21: 3
A22: Geografia | B22: LIC | D22: Cametá | E22: CMT | F22: 201501042 | G22: 123734 | H22: 2018 | I22: 09/05 | J22: 3.7 | K22: 4.58 | L22: 3 | M22: 4 | N22: 4
A23: Ciencias Sociais - BACH | B23: BACH | D23: Belém | E23: IFCH | F23: 201506093 | G23: 124705 | H23: 2018 | I23: 09/05 | J23: 3.2 | K23: 4.73 | L23: 4 | M23: 4 | N23: 4
A24: Letras Português | B24: LIC | D24: Belém | E24: ILC | F24: 201607682 | G24: 130677 | H24: 2018 | I24: 09/05 | J24: 3.5 | K24: 4.25 | L24: 3.25 | M24: 4 | N24: 4
A25: Eng. Florestal | B25: BACH | D25: Altamira | E25: ALT | F25: 201616945 | G25: 135898 | H25: 2018 | I25: 16/06 | J25: 3.67 | K25: 4.18 | L25: 3.4 | M25: 4 | N25: 2
... A38: História | B38: LIC | D38: Ananindeua | E38: ANA | F38: 201815395 | G38: 148025 | H38: 2018 | I38: 09/12 | J38: 4.28 | K38: 4.44 | L38: 3 | M38: 4 | N38: 1
I39: Média | J39: =AVERAGE(J14:J38) -> 3.896 | K39: =AVERAGE(K14:K38) -> 4.3504 | L39: =AVERAGE(L14:L38) -> 3.7476 | M39: =AVERAGE(M14:M38) -> 4 | N39: =AVERAGE(N14:N38) -> 3.32

Sheet 2018 (GRAF)
A1: UNIVERSIDADE FEDERAL DO PARA
A2: PRÓ-REITORIA DE PLANEJAMENTO E DESENVOLVIMENTO INSTITUCIONAL
A3: DIRETORIA DE AVALIAÇÃO INSTITUCIONAL
A4: COORDENADORIA DE AUTOAVALIAÇÃO
D14: UND-ACAD | E14: D1 | F14: D2 | G14: D3
D15: ABT | E15: =AVERAGE('2018'!J33) -> 3.25 | F15: =AVERAGE('2018'!K33) -> 4.08 | G15: =AVERAGE('2018'!L33) -> 2.91
D16: ALT | E16: =AVERAGE('2018'!J20,'2018'!J25) -> 4.21 | F16: =AVERAGE('2018'!K20,'2018'!K25) -> 4.59 | G16: =AVERAGE('2018'!L20,'2018'!L25) -> 3.81
D17: ANA | E17: =AVERAGE('2018'!J38) -> 4.28 | F17: =AVERAGE('2018'!K38) -> 4.44 | G17: =AVERAGE('2018'!L38) -> 3
D18: BRG | E18: =AVERAGE('2018'!J18) -> 4.47 | F18: =AVERAGE('2018'!K18) -> 4.64 | G18: =AVERAGE('2018'!L18) -> 3.91
D19: BRV | E19: =AVERAGE('2018'!J14) -> 4.19 | F19: =AVERAGE('2018'!K14) -> 4.42 | G19: =AVERAGE('2018'!L14) -> 3.88
D20: CMT | E20: =AVERAGE('2018'!J22,'2018'!J34) -> 3.3 | F20: =AVERAGE('2018'!K22,'2018'!K34) -> 4.415 | G20: =AVERAGE('2018'!L22,'2018'!L34) -> 3
D21: CST | E21: =AVERAGE('2018'!J19) -> 3.65 | F21: =AVERAGE('2018'!K19) -> 4.14 | G21: =AVERAGE('2018'!L19) -> 3.4
D22: ICA | E22: =AVERAGE('2018'!J21) -> 4.4 | F22: =AVERAGE('2018'!K21) -> 4.17 | G22: =AVERAGE('2018'!L21) -> 4
D23: ICB | E23: =AVERAGE('2018'!J26) -> 4 | F23: =AVERAGE('2018'!K26) -> 4.64 | G23: =AVERAGE('2018'!L26) -> 4.13
D24: ICS | E24: =AVERAGE('2018'!J16,'2018'!J17) -> 4.49 | F24: =AVERAGE('2018'!K16,'2018'!K17) -> 4.83 | G24: =AVERAGE('2018'!L16,'2018'!L17) -> 4.29
D25: ICSA | E25: =AVERAGE('2018'!J37) -> 3.86 | F25: =AVERAGE('2018'!K37) -> 4.33 | G25: =AVERAGE('2018'!L37) -> 4.25
D26: IEMCI | E26: =AVERAGE('2018'!J27) -> 4 | F26: =AVERAGE('2018'!K27) -> 4.92 | G26: =AVERAGE('2018'!L27) -> 4.3
D27: IFCH | E27: =AVERAGE('2018'!J23) -> 3.2 | F27: =AVERAGE('2018'!K23) -> 4.73 | G27: =AVERAGE('2018'!L23) -> 4
D28: IG | E28: =AVERAGE('2018'!J32) -> 3.36 | F28: =AVERAGE('2018'!K32) -> 4.46 | G28: =AVERAGE('2018'!L32) -> 3.44
D29: ILC | E29: =AVERAGE('2018'!J24,'2018'!J28,'2018'!J29,'2018'!J30,'2018'!J31) -> 3.86 | F29: =AVERAGE('2018'!K24,'2018'!K28,'2018'!K29,'2018'!K30,'2018'!K31) -> 3.914 | G29: =AVERAGE('2018'!L24,'2018'!L28,'2018'!L29,'2018'!L30,'2018'!L31) -> 4.054
D30: SAL | E30: =AVERAGE('2018'!J35) -> 4.11 | F30: =AVERAGE('2018'!K35) -> 4 | G30: =AVERAGE('2018'!L35) -> 4
D31: TUC | E31: =AVERAGE('2018'!J36,'2018'!J15) -> 3.665 | F31: =AVERAGE('2018'!K36,'2018'!K15) -> 4.275 | G31: =AVERAGE('2018'!L36,'2018'!L15) -> 3
A38: D1 - ORGANIZAÇÃO DIDÁTICO-PEDAGÓGICA - Fontes de Consulta: Plano de Desenvolvimento Institucional, Projeto Pedagógico do Curso, Relatório de Autoavaliação Institucional, Políticas Institucionais, Diretrizes Curriculares Nacionais, quando houver, Catálogo Nacional dos Cursos Superiores de Tecnologia, quando couber, Formulário Eletrônico preenchido pela IES no e-MEC.
A40: D2 - CORPO DOCENTE E TUTORIAL - Fontes de consulta: Projeto Pedagógico do Curso, Plano de Desenvolvimento Institucional, Políticas de Formação Docente, Formulário Eletrônico preenchido pela IES no e-MEC, Documentação Comprobatória e Catálogo Nacional dos Cursos Superiores de Tecnologia, quando couber.
A42: D3 - INFRAESTRUTURA - Fontes de Consulta: Projeto Pedagógico do Curso, Diretrizes Curriculares Nacionais, quando houver, Catálogo Nacional dos Cursos Superiores de Tecnologia, quando couber. Formulário Eletrônico preenchido pela IES no e-MEC e Documentação Comprobatória.

Sheet 2019
F1: UNIVERSIDADE FEDERAL DO PARA
F2: PRÓ-REITORIA DE PLANEJAMENTO E DESENVOLVIMENTO INSTITUCIONAL
F3: DIRETORIA DE AVALIAÇÃO INSTITUCIONAL
F4: COORDENADORIA DE AUTOAVALIAÇÃO
D9: MOSTRA O RELATÓRIO DA AVALIAÇÃO
A11: Curso | B11: MOD | C11: COD_CURSO | D11: Campus | E11: UND-ACAD | F11: Nº PROC | G11: Nº AVAL | H11: ANO AVAL | I11: INICIO | J11: D1 | K11: D2 | L11: D3 | M11: CC | N11: AVAL
A12: FISICA | B12: LIC | D12: ANANINDEUA | E12: ANA | F12: 201815397 | G12: 148248 | H12: 2019 | I12: 03/02 | J12: 3.89 | K12: 3.67 | L12: 2.63 | M12: 3 | N12: 1
A13: QUIMICA | B13: LIC | D13: ANANINDEUA | E13: ANA | F13: 201815398 | G13: 148085 | H13: 2019 | I13: 03/02 | J13: 4.33 | K13: 3.67 | L13: 3 | M13: 4 | N13: 1
A14: GEOGRAFIA | B14: LIC | D14: ANANINDEUA | E14: ANA | F14: 201815396 | G14: 148061 | H14: 2019 | I14: 03/02 | J14: 4.06 | K14: 3.78 | L14: 3.11 | M14: 4 | N14: 4
A15: ARTES VISUAIS | B15: BACH | D15: BELEM | E15: ICA | F15: 201721935 | G15: 144753 | H15: 2019 | I15: 17/03 | J15: 3.93 | K15: 3.89 | L15: 4 | M15: 4 | N15: 5
A16: ESTATISTICA | B16: BACH | D16: BELEM | E16: ICEN | F16: 201721939 | G16: 147073 | H16: 2019 | I16: 27/03 | J16: 4.43 | K16: 4.89 | L16: 4.43 | M16: 5 | N16: 5
A17: TEATRO | B17: BACH | D17: BELEM | E17: ICA | F17: 201616686 | G17: 137587 | H17: 2019 | I17: 03/04 | J17: 4.95 | K17: 4.92 | L17: 3.73 | M17: 5 | N17: 5
A18: DANÇA | B18: LIC | D18: BELEM | E18: ICA | F18: 201616907 | G18: 135895 | H18: 2019 | I18: 30/06 | J18: 4.5 | K18: 4.92 | L18: 4.09 | M18: 5 | N18: 4
A19: MUSEOLOGIA | B19: BACH | D19: BELEM | E19: ICA | F19: 201721940 | G19: 147074 | H19: 2019 | I19: 17/10 | J19: 3.86 | K19: 4.33 | L19: 3.63 | M19: 4 | N19: 3
A20: PRODUÇÃO MULTIMIDIA | B20: TEC | D20: BELEM | E20: ICA | F20: 201721941 | G20: 144767 | H20: 2019 | I20: 17/10 | J20: 4.79 | K20: 3.22 | L20: 4.33 | M20: 4 | N20: 5
A21: QUIMICA INDUSTRIAL | B21: BACH | D21: BELEM | E21: ICEN | F21: 201616945 | G21: 153061 | H21: 2019 | I21: 28/11 | J21: 4.67 | K21: 4.55 | L21: 4.67 | M21: 5 | N21: 3
A22: BIOMEDICINA | B22: BACH | D22: BELEM | E22: ICB | F22: 201816735 | G22: 154248 | H22: 2019 | I22: 02/12 | J22: 3.07 | K22: 3.56 | L22: 2.85 | M22: 3 | N22: 3
A23: AGRONOMIA | B23: BACH | D23: ALTAMIRA | E23: ALT | F23: 201816736 | G23: 154249 | H23: 2019 | I23: 12/12 | J23: 3.79 | K23: 3.44 | L23: 3.63 | M23: 4 | N23: 4
A24: ODONTOLOGIA | B24: BACH | D24: BELEM | E24: ICS | F24: 201813443 | G24: 155171 | H24: 2019 | I24: 12/12 | J24: 1.87 | K24: 3.67 | L24: 2.4 | M24: 3 | N24: 1
I25: Média | J25: =AVERAGE(J12:J24) -> 4.0107692 | K25: =AVERAGE(K12:K24) -> 4.0392308 | L25: =AVERAGE(L12:L24) -> 3.5769231 | M25: =AVERAGE(M12:M24) -> 4.0769231 | N25: =AVERAGE(N12:N24) -> 3.3846154

Sheet 2019 (GRAF)
A1: UNIVERSIDADE FEDERAL DO PARA
A2: PRÓ-REITORIA DE PLANEJAMENTO E DESENVOLVIMENTO INSTITUCIONAL
A3: DIRETORIA DE AVALIAÇÃO INSTITUCIONAL
A4: COORDENADORIA DE AUTOAVALIAÇÃO
C16: UND-ACAD | D16: D1 | E16: D2 | F16: D3
C17: ALT | D17: =AVERAGE('2019'!J23) -> 3.79 | E17: =AVERAGE('2019'!K23) -> 3.44 | F17: =AVERAGE('2019'!L23) -> 3.63
C18: ANA | D18: =AVERAGE('2019'!J12:J14) -> 4.0933333 | E18: =AVERAGE('2019'!K12:K14) -> 3.7066667 | F18: =AVERAGE('2019'!L12:L14) -> 2.9133333
C19: ICA | D19: =AVERAGE('2019'!J15,'2019'!J17,'2019'!J18,'2019'!J19,'2019'!J20) -> 4.406 | E19: =AVERAGE('2019'!K15,'2019'!K17,'2019'!K18,'2019'!K19,'2019'!K20) -> 4.256 | F19: =AVERAGE('2019'!L15,'2019'!L17,'2019'!L18,'2019'!L19,'2019'!L20) -> 3.956
C20: ICEN | D20: =AVERAGE('2019'!J16,'2019'!J21) -> 4.55 | E20: =AVERAGE('2019'!K16,'2019'!K21) -> 4.72 | F20: =AVERAGE('2019'!L16,'2019'!L21) -> 4.55
C21: ICS | D21: =AVERAGE('2019'!J24) -> 1.87 | E21: =AVERAGE('2019'!K24) -> 3.67 | F21: =AVERAGE('2019'!L24) -> 2.4
A34: D1 - ORGANIZAÇÃO DIDÁTICO-PEDAGÓGICA - Fontes de Consulta: Plano de Desenvolvimento Institucional, Projeto Pedagógico do Curso, Relatório de Autoavaliação Institucional, Políticas Institucionais, Diretrizes Curriculares Nacionais, quando houver, Catálogo Nacional dos Cursos Superiores de Tecnologia, quando couber, Formulário Eletrônico preenchido pela IES no e-MEC.
A36: D2 - CORPO DOCENTE E TUTORIAL - Fontes de consulta: Projeto Pedagógico do Curso, Plano de Desenvolvimento Institucional, Políticas de Formação Docente, Formulário Eletrônico preenchido pela IES no e-MEC, Documentação Comprobatória e Catálogo Nacional dos Cursos Superiores de Tecnologia, quando couber.
A38: D3 - INFRAESTRUTURA - Fontes de Consulta: Projeto Pedagógico do Curso, Diretrizes Curriculares Nacionais, quando houver, Catálogo Nacional dos Cursos Superiores de Tecnologia, quando couber. Formulário Eletrônico preenchido pela IES no e-MEC e Documentação Comprobatória.

Sheet 2020
A1: UNIVERSIDADE FEDERAL DO PARA
A2: PRÓ-REITORIA DE PLANEJAMENTO E DESENVOLVIMENTO INSTITUCIONAL
A3: DIRETORIA DE AVALIAÇÃO INSTITUCIONAL
A4: COORDENADORIA DE AUTOAVALIAÇÃO
D9: MOSTRA O RELATÓRIO DA AVALIAÇÃO
A11: Curso | B11: MOD | C11: COD-CURSO | D11: Campus | E11: UND-ACAD | F11: Nº PROC | G11: Nº AVAL | H11: ANO-AVAL | I11: INICIO | J11: D1 | K11: D2 | L11: D3 | M11: CC | N11: AVAL
A12: Enfermagem | B12: BACH | D12: Belem | E12: ICS | F12: 201812688 | G12: 155170 | H12: 2020 | I12: 16/03/2020 | J12: 3.13 | K12: 3 | L12: 3.25 | M12: 3 | N12: 3
I13: Média | J13: =AVERAGE(J12:J12) -> 3.13 | K13: =AVERAGE(K12:K12) -> 3 | L13: =AVERAGE(L12:L12) -> 3.25 | M13: =AVERAGE(M12:M12) -> 3 | N13: =AVERAGE(N12:N12) -> 3

Sheet 2020 (GRAF)
A1: UNIVERSIDADE FEDERAL DO PARA
A2: PRÓ-REITORIA DE PLANEJAMENTO E DESENVOLVIMENTO INSTITUCIONAL
A3: DIRETORIA DE AVALIAÇÃO INSTITUCIONAL
A4: COORDENADORIA DE AUTOAVALIAÇÃO
C16: UND-ACAD | D16: D1 | E16: D2 | F16: D3
C17: ='2020'!E12 -> ICS | D17: ='2020'!J12 -> 3.13 | E17: ='2020'!K12 -> 3 | F17: ='2020'!L12 -> 3.25
A34: D1 - ORGANIZAÇÃO DIDÁTICO-PEDAGÓGICA - Fontes de Consulta: Plano de Desenvolvimento Institucional, Projeto Pedagógico do Curso, Relatório de Autoavaliação Institucional, Políticas Institucionais, Diretrizes Curriculares Nacionais, quando houver, Catálogo Nacional dos Cursos Superiores de Tecnologia, quando couber, Formulário Eletrônico preenchido pela IES no e-MEC.
A36: D2 - CORPO DOCENTE E TUTORIAL - Fontes de consulta: Projeto Pedagógico do Curso, Plano de Desenvolvimento Institucional, Políticas de Formação Docente, Formulário Eletrônico preenchido pela IES no e-MEC, Documentação Comprobatória e Catálogo Nacional dos Cursos Superiores de Tecnologia, quando couber.
A38: D3 - INFRAESTRUTURA - Fontes de Consulta: Projeto Pedagógico do Curso, Diretrizes Curriculares Nacionais, quando houver, Catálogo Nacional dos Cursos Superiores de Tecnologia, quando couber. Formulário Eletrônico preenchido pela IES no e-MEC e Documentação Comprobatória.

Sheet 2021
A1: UNIVERSIDADE FEDERAL DO PARA
A2: PRÓ-REITORIA DE PLANEJAMENTO E DESENVOLVIMENTO INSTITUCIONAL
A3: DIRETORIA DE AVALIAÇÃO INSTITUCIONAL
A4: COORDENADORIA DE AUTOAVALIAÇÃO
D9: MOSTRA O RELATÓRIO DA AVALIAÇÃO
A11: Curso | B11: MOD | C11: COD_CURSO | D11: Campus | E11: UND-ACAD | F11: Nº PROC | G11: Nº AVAL | H11: ANO-AVAL | I11: INICIO | J11: D1 | K11: D2 | L11: D3 | M11: CC | N11: AVAL
A12: Física | B12: LIC | D12: Ananindeua | E12: ANA | F12: 201815397 | G12: 160983 | H12: 2021 | I12: 15/07/2021 | J12: 4.56 | K12: 4.67 | L12: 3.67 | M12: 4 | N12: 5
I13: Média | J13: =AVERAGE(J12:J12) -> 4.56 | K13: =AVERAGE(K12:K12) -> 4.67 | L13: =AVERAGE(L12:L12) -> 3.67 | M13: =AVERAGE(M12:M12) -> 4 | N13: =AVERAGE(N12:N12) -> 5

Sheet 2021 (GRAF)
A1: UNIVERSIDADE FEDERAL DO PARA
A2: PRÓ-REITORIA DE PLANEJAMENTO E DESENVOLVIMENTO INSTITUCIONAL
A3: DIRETORIA DE AVALIAÇÃO INSTITUCIONAL
A4: COORDENADORIA DE AUTOAVALIAÇÃO
C16: UND-ACAD | D16: D1 | E16: D2 | F16: D3
C17: ANA | D17: 4.56 | E17: 4.67 | F17: 3.67
A34: D1 - ORGANIZAÇÃO DIDÁTICO-PEDAGÓGICA - Fontes de Consulta: Plano de Desenvolvimento Institucional, Projeto Pedagógico do Curso, Relatório de Autoavaliação Institucional, Políticas Institucionais, Diretrizes Curriculares Nacionais, quando houver, Catálogo Nacional dos Cursos Superiores de Tecnologia, quando couber, Formulário Eletrônico preenchido pela IES no e-MEC.
